<?xml version="1.0" encoding="utf-8"?>
<!-- This URDF was automatically created by SolidWorks to URDF Exporter! Originally created by
Stephen Brawner (brawner@gmail.com) 
     Commit Version: 1.6.0-4-g7f85cfe  Build Version: 1.6.7995.38578
     For more information, please see http://wiki.ros.org/sw_urdf_exporter -->

<robot name="HU_B03_01">

    <!--    <link name="root_link">-->
    <!--        <inertial>-->
    <!--            <origin xyz="0 0 0" rpy="0 0 0"/>-->
    <!--            <mass value="0.001"/>-->
    <!--            <inertia ixx="1E-10" ixy="0" ixz="0" iyy="1E-10" iyz="0" izz="1E-10"/>-->
    <!--        </inertial>-->
    <!--    </link>-->
    <!--    <joint name="floating_base_joint" type="floating">-->
    <!--        <origin xyz="0.0 0.0 0.0" rpy="0 0 0"/>-->
    <!--        <parent link="root_link"/>-->
    <!--        <child link="base_link"/>-->
    <!--    </joint>-->

    <link name="base_link">
        <!-- <inertial>
          <origin
            xyz="-0.014811 0.0 0.178687"
            rpy="0 0 0" />
          <mass value="14.732" />
          <inertia
            ixx="470802.025851E-06"
            ixy="85.540265E-06"
            ixz="-79050.910839E-06"
            iyy="438489.039949E-06"
            iyz="134.494543E-06"
            izz="121110.125699E-06" />
        </inertial> -->

        <inertial>       <!-- with ID -->
            <origin
                    xyz="-0.016868 0.0 0.198217"
                    rpy="0 0 0"/>
            <mass value="16.207"/>
            <inertia
                    ixx="572460.409385E-06"
                    ixy="85.854370E-06"
                    ixz="-67819.943296E-06"
                    iyy="534400.875589E-06"
                    iyz="110.253134E-06"
                    izz="130292.833139E-06"/>
        </inertial>
        <visual>
            <origin
                    xyz="0 0 0"
                    rpy="0 0 0"/>
            <geometry>
                <mesh
                        filename="../meshes/base_link.STL"/>
            </geometry>
            <material name="">
                <color rgba="0.890196078431372 0.890196078431372 0.913725490196078 1"/>
            </material>
        </visual>
        <collision>
            <origin
                    xyz="0.02 0 0.26"
                    rpy="0 0 0"/>
            <geometry>
                <box size="0.16 0.2 0.46"/>
            </geometry>
        </collision>
    </link>

    <!-- Imu is fixed to the base link -->
    <joint name="limx_imu_joint" type="fixed">
        <origin rpy="0. 0. 0." xyz="0 0 0"/>
        <parent link="base_link"/>
        <child link="limx_imu"/>
    </joint>
    <!-- Imu link -->
    <link name="limx_imu">
        <inertial>
            <mass value="0.001"/>
            <origin rpy="0 0 0" xyz="0 0 0"/>
            <inertia ixx="0.000001" ixy="0" ixz="0" iyy="0.000001" iyz="0" izz="0.000001"/>
        </inertial>
        <visual>
            <origin rpy="0 0 0" xyz="0 0 0"/>
            <geometry>
                <box size="0.015 0.015 0.004"/>
            </geometry>
        </visual>
        <material name="orange">
            <color rgba="255 108 10 255"/>
        </material>
    </link>

    <!-- left arm -->
    <joint name="shoulder_pitch_joint_L" type="revolute">
        <origin xyz="0 0.1216 0.41834" rpy="0 0 0"/>
        <parent link="base_link"/>
        <child link="shoulder_pitch_L"/>
        <axis xyz="0 -1 0"/>
        <limit
                lower="-0.7854"
                upper="2.0944"
                effort="40"
                velocity="10"/>
    </joint>
    <link name="shoulder_pitch_L">
        <inertial>
            <origin
                    xyz="0.0 0.0568 0.0"
                    rpy="0 0 0"/>
            <mass value="0.958"/>
            <inertia
                    ixx="990.388E-06"
                    ixy="-31.054E-06"
                    ixz="3.076E-06"
                    iyy="825.093E-06"
                    iyz="8.451E-06"
                    izz="1043.555E-06"/>
        </inertial>
        <visual>
            <origin
                    xyz="0 0 0"
                    rpy="0 0 0"/>
            <geometry>
                <mesh filename="../meshes/shoulder_pitch_L.STL"/>
            </geometry>
            <material name="">
                <color rgba="0.890196078431372 0.890196078431372 0.913725490196078 1"/>
            </material>
        </visual>
    </link>

    <joint name="shoulder_roll_joint_L" type="revolute">
        <origin xyz="0.0275 0.0636 0" rpy="0 0 0"/>
        <parent link="shoulder_pitch_L"/>
        <child link="shoulder_roll_L"/>
        <axis xyz="-1 0 0"/>
        <limit
                lower="-1.7453"
                upper="0.0873"
                effort="40"
                velocity="10"/>
    </joint>
    <link name="shoulder_roll_L">
        <inertial>
            <origin
                    xyz="-0.025 0.0 -0.075"
                    rpy="0 0 0"/>
            <mass value="0.929"/>
            <inertia
                    ixx="1371.975032E-06"
                    ixy="-1.029439E-06"
                    ixz="-221.939509E-06"
                    iyy="1515.198843E-06"
                    iyz="-0.435620E-06"
                    izz="873.513514E-06"/>
        </inertial>
        <visual>
            <origin
                    xyz="0 0 0"
                    rpy="0 0 0"/>
            <geometry>
                <mesh filename="../meshes/shoulder_roll_L.STL"/>
            </geometry>
            <material name="">
                <color rgba="0.890196078431372 0.890196078431372 0.913725490196078 1"/>
            </material>
        </visual>
    </link>

    <joint name="shoulder_yaw_joint_L" type="revolute">
        <origin xyz="-0.0275 0 -0.112" rpy="0 0 0"/>
        <parent link="shoulder_roll_L"/>
        <child link="shoulder_yaw_L"/>
        <axis xyz="0 0 1"/>
        <limit
                lower="-0.7854"
                upper="1.5708"
                effort="40"
                velocity="10"/>
    </joint>
    <link name="shoulder_yaw_L">
        <inertial>
            <origin
                    xyz="-0.00086 0.0 -0.14858"
                    rpy="0 0 0"/>
            <mass value="1.075"/>
            <inertia
                    ixx="3440.482150E-06"
                    ixy="-2.799463E-06"
                    ixz="-40.730553E-06"
                    iyy="3425.016102E-06"
                    iyz="44.252680E-06"
                    izz="865.590773E-06"/>
        </inertial>
        <visual>
            <origin
                    xyz="0 0 0"
                    rpy="0 0 0"/>
            <geometry>
                <mesh filename="../meshes/shoulder_yaw_L.STL"/>
            </geometry>
            <material name="">
                <color rgba="0.898039215686275 0.917647058823529 0.929411764705882 1"/>
            </material>
        </visual>
        <collision>
            <origin rpy="0 0 0" xyz="0 0 -0.02"/>
            <geometry>
                <cylinder radius="0.04" length="0.16"/>
            </geometry>
        </collision>
    </link>

    <joint name="elbow_joint_L" type="revolute">
        <origin xyz="0 0.0275 -0.1719" rpy="0 0 0"/>
        <parent link="shoulder_yaw_L"/>
        <child link="elbow_L"/>
        <axis xyz="0 1 0"/>
        <limit
                lower="-0.5787"
                upper="1.5708"
                effort="40"
                velocity="10"/>
    </joint>
    <link name="elbow_L">
        <inertial>
            <origin
                    xyz="0.08954 -0.0209 -0.000106"
                    rpy="0 0 0"/>
            <mass value="0.278"/>
            <inertia
                    ixx="217.677566E-06"
                    ixy="164.011059E-06"
                    ixz="-1.889902E-06"
                    iyy="2128.203072E-06"
                    iyz="0.871789E-06"
                    izz="2247.922760E-06"/>
        </inertial>
        <visual>
            <origin
                    xyz="0 0 0"
                    rpy="0 0 0"/>
            <geometry>
                <mesh filename="../meshes/elbow_L.STL"/>
            </geometry>
            <material name="">
                <color rgba="0.890196078431372 0.890196078431372 0.913725490196078 1"/>
            </material>
        </visual>
        <collision>
            <origin
                    xyz="0 0 0"
                    rpy="0 0 0"/>
            <geometry>
                <mesh filename="../meshes/elbow_L.STL"/>
            </geometry>
        </collision>
    </link>

    <!-- left arm contact -->
    <joint name="contact_hand_joint_L" type="fixed" dont_collapse="true">
        <origin xyz="0.274 -0.0275 0.0" rpy="0 0 0"/>
        <parent link="elbow_L"/>
        <child link="contact_hand_L"/>
    </joint>
    <link name="contact_hand_L">
        <inertial>
            <origin xyz=".0 .0 .0" rpy="0 0 0"/>
            <mass value="0.001"/>
            <inertia ixx="0.0000001" ixy="0.0" ixz="0.0" iyy="0.0000001" iyz="0.0" izz="0.0000001"/>
        </inertial>
        <visual>
            <origin
                    xyz="0 0 0"
                    rpy="0 0 0"/>
            <geometry>
                <box size="0.01 0.01 0.01"/>
            </geometry>
            <material name="">
                <color rgba="1 0 0 1"/>
            </material>
        </visual>
    </link>

    <!-- Left Leg -->
    <joint name="hip_roll_joint_L" type="revolute">
        <origin xyz="-0.068 0.118 -0.03116" rpy="0 0 0"/>
        <parent link="base_link"/>
        <child link="hip_roll_L"/>
        <axis xyz="-1 0 0"/>
        <limit
                lower="-0.5236"
                upper="0.5236"
                effort="120"
                velocity="20"/>
    </joint>
    <link name="hip_roll_L">
        <inertial>
            <origin
                    xyz="0.0711 0 0.0032"
                    rpy="0 0 0"/>
            <mass value="1.353"/>
            <inertia
                    ixx="1474.595577E-06"
                    ixy="0.035621E-06"
                    ixz="2.830837E-06"
                    iyy="2445.648862E-06"
                    iyz="-4.252336E-06"
                    izz="2855.882505E-06"/>
        </inertial>
        <visual>
            <origin
                    xyz="0 0 0"
                    rpy="0 0 0"/>
            <geometry>
                <mesh filename="../meshes/hip_roll_L.STL"/>
            </geometry>
            <material name="">
                <color rgba="0.792156862745098 0.819607843137255 0.933333333333333 1"/>
            </material>
        </visual>
        <collision>
            <origin
                    xyz="-0.04 0 0"
                    rpy="0 0 0"/>
            <geometry>
                <box size="0.07 0.1 0.1"/>
            </geometry>
        </collision>
    </link>


    <joint name="hip_yaw_joint_L" type="revolute">
        <origin xyz="0.068 0 -0.0195" rpy="0 0 0"/>
        <parent link="hip_roll_L"/>
        <child link="hip_yaw_L"/>
        <axis xyz="0 0 -1"/>
        <limit
                lower="-0.7854"
                upper="0.7854"
                effort="120"
                velocity="20"/>
    </joint>
    <link name="hip_yaw_L">
        <inertial>
            <origin
                    xyz="0 -0.03166 -0.0877"
                    rpy="0 0 0"/>
            <mass value="1.999"/>
            <inertia
                    ixx="6363.143641E-06"
                    ixy="-2.235936E-06"
                    ixz="-1.625167E-06"
                    iyy="6565.890011E-06"
                    iyz="-1068.019977E-06"
                    izz="4234.229362E-06"/>
        </inertial>
        <visual>
            <origin
                    xyz="0 0 0"
                    rpy="0 0 0"/>
            <geometry>
                <mesh filename="../meshes/hip_yaw_L.STL"/>
            </geometry>
            <material name="">
                <color rgba="0.792156862745098 0.819607843137255 0.933333333333333 1"/>
            </material>
        </visual>
    </link>


    <joint name="hip_pitch_joint_L" type="revolute">
        <origin xyz="0 -0.024 -0.103" rpy="0 0 0"/>
        <parent link="hip_yaw_L"/>
        <child link="hip_pitch_L"/>
        <axis xyz="0 -1 0"/>
        <limit
                lower="-1.5359"
                upper="1.0472"
                effort="120"
                velocity="20"/>
    </joint>
    <link name="hip_pitch_L">
        <inertial>
            <origin
                    xyz="0.0202 0.055 -0.03835"
                    rpy="0 0 0"/>
            <mass value="4.306"/>
            <inertia
                    ixx="39234.883902E-06"
                    ixy="2770.935796E-06"
                    ixz="16398.509235E-06"
                    iyy="49317.347468E-06"
                    iyz="-5316.711707E-06"
                    izz="18132.628369E-06"/>
        </inertial>
        <visual>
            <origin
                    xyz="0 0 0"
                    rpy="0 0 0"/>
            <geometry>
                <mesh filename="../meshes/hip_pitch_L.STL"/>
            </geometry>
            <material name="">
                <color rgba="0.898039215686275 0.917647058823529 0.929411764705882 1"/>
            </material>
        </visual>
        <collision>
            <origin rpy="1.57 0 0" xyz="0 0.02 0"/>
            <geometry>
                <cylinder radius="0.07" length="0.18"/>
            </geometry>
        </collision>
        <collision>
            <origin rpy="1.57 -0.45 0" xyz="0.1 0.025 -0.18"/>
            <geometry>
                <box size="0.1 0.24 0.04"/>
            </geometry>
        </collision>
    </link>


    <joint name="knee_joint_L" type="revolute">
        <origin xyz="0.175 0.024 -0.30311" rpy="0 0 0"/>
        <parent link="hip_pitch_L"/>
        <child link="knee_L"/>
        <axis xyz="0 -1 0"/>
        <limit
                lower="-1.0472"
                upper="0.6981"
                effort="180"
                velocity="20"/>
    </joint>
    <link name="knee_L">
        <inertial>
            <origin
                    xyz="-0.06018 -0.00312 -0.1125"
                    rpy="0 0 0"/>
            <mass value="1.694"/>
            <inertia
                    ixx="13325.678709E-06"
                    ixy="520.920143E-06"
                    ixz="-7926.961445E-06"
                    iyy="18655.420898E-06"
                    iyz="478.732558E-06"
                    izz="6610.199995E-06"/>
        </inertial>
        <visual>
            <origin
                    xyz="0 0 0"
                    rpy="0 0 0"/>
            <geometry>
                <mesh filename="../meshes/knee_L.STL"/>
            </geometry>
            <material name="">
                <color rgba="0.898039215686275 0.917647058823529 0.929411764705882 1"/>
            </material>
        </visual>
        <collision>
            <origin rpy="1.57 0.6 0" xyz="-0.12 -0.0 -0.18"/>
            <geometry>
                <box size="0.08 0.24 0.04"/>
            </geometry>
        </collision>
    </link>


    <joint name="ankle_joint_L" type="revolute">
        <origin xyz="-0.175 0 -0.30311" rpy="0 0 0"/>
        <parent link="knee_L"/>
        <child link="ankle_L"/>
        <axis xyz="0 -1 0"/>
        <limit
                lower="-1.2566"
                upper="0.6109"
                effort="40"
                velocity="10"/>
    </joint>
    <link name="ankle_L">
        <inertial>
            <origin
                    xyz="-0.01054 0.001 -0.021"
                    rpy="0 0 0"/>
            <mass value="0.404"/>
            <inertia
                    ixx="164.737831E-06"
                    ixy="15.856723E-06"
                    ixz="68.793585E-06"
                    iyy="1149.965027E-06"
                    iyz="-8.127539E-06"
                    izz="1159.669589E-06"/>
        </inertial>
        <visual>
            <origin
                    xyz="0 0 0"
                    rpy="0 0 0"/>
            <geometry>
                <mesh filename="../meshes/ankle_L.STL"/>
            </geometry>
            <material name="">
                <color rgba="0.898039215686275 0.917647058823529 0.929411764705882 1"/>
            </material>
        </visual>
        <collision>
            <origin rpy="0 0 0" xyz="0.0 0.0 -0.029"/>
            <geometry>
                <box size="0.21 0.06 0.02"/>
            </geometry>
        </collision>
        <!-- <collision>
          <origin
            xyz="0 0 0"
            rpy="0 0 0" />
          <geometry>
            <mesh filename="../meshes/ankle_L.STL" />
          </geometry>
        </collision> -->
    </link>

    <!-- Left Foot Contact -->
    <joint name="contact_foot_heel_joint_L" type="fixed">
        <origin xyz="-0.105 0 -0.039" rpy="0 0 0"/>
        <parent link="ankle_L"/>
        <child link="contact_foot_heel_L"/>
    </joint>
    <link name="contact_foot_heel_L">
        <inertial>
            <origin xyz=".0 .0 .0" rpy="0 0 0"/>
            <mass value="0.001"/>
            <inertia ixx="0.0000001" ixy="0.0" ixz="0.0" iyy="0.0000001" iyz="0.0" izz="0.0000001"/>
        </inertial>
        <visual>
            <origin xyz="0 0 0" rpy="0 0 0"/>
            <geometry>
                <box size="0.01 0.01 0.01"/>
            </geometry>
            <material name="">
                <color rgba="1 0 0 1"/>
            </material>
        </visual>
    </link>

    <joint name="contact_foot_tip_joint_L" type="fixed">
        <origin xyz="0.105 0 -0.039" rpy="0 0 0"/>
        <parent link="ankle_L"/>
        <child link="contact_foot_tip_L"/>
    </joint>
    <link name="contact_foot_tip_L">
        <inertial>
            <origin xyz=".0 .0 .0" rpy="0 0 0"/>
            <mass value="0.001"/>
            <inertia ixx="0.0000001" ixy="0.0" ixz="0.0" iyy="0.0000001" iyz="0.0" izz="0.0000001"/>
        </inertial>
        <visual>
            <origin xyz="0 0 0" rpy="0 0 0"/>
            <geometry>
                <box size="0.01 0.01 0.01"/>
            </geometry>
            <material name="">
                <color rgba="1 0 0 1"/>
            </material>
        </visual>
    </link>

    <joint name="contact_foot_center_joint_L" type="fixed">
        <origin xyz="0 0 -0.039" rpy="0 0 0"/>
        <parent link="ankle_L"/>
        <child link="contact_foot_center_L"/>
    </joint>
    <link name="contact_foot_center_L">
        <inertial>
            <origin xyz=".0 .0 .0" rpy="0 0 0"/>
            <mass value="0.001"/>
            <inertia ixx="0.0000001" ixy="0.0" ixz="0.0" iyy="0.0000001" iyz="0.0" izz="0.0000001"/>
        </inertial>
        <visual>
            <origin xyz="0 0 0" rpy="0 0 0"/>
            <geometry>
                <box size="0.01 0.01 0.01"/>
            </geometry>
            <material name="">
                <color rgba="1 0 0 1"/>
            </material>
        </visual>
    </link>

    <!-- right arm -->
    <joint name="shoulder_pitch_joint_R" type="revolute">
        <origin xyz="0 -0.1216 0.41834" rpy="0 0 0"/>
        <parent link="base_link"/>
        <child link="shoulder_pitch_R"/>
        <axis xyz="0 -1 0"/>
        <limit
                lower="-0.7854"
                upper="2.0944"
                effort="40"
                velocity="10"/>
    </joint>
    <link name="shoulder_pitch_R">
        <inertial>
            <origin
                    xyz="0.0 -0.0568 0.0"
                    rpy="0 0 0"/>
            <mass value="0.958"/>
            <inertia
                    ixx="990.388E-06"
                    ixy="31.054E-06"
                    ixz="3.076E-06"
                    iyy="825.093E-06"
                    iyz="-8.451E-06"
                    izz="1043.555E-06"/>
        </inertial>
        <visual>
            <origin
                    xyz="0 0 0"
                    rpy="0 0 0"/>
            <geometry>
                <mesh filename="../meshes/shoulder_pitch_R.STL"/>
            </geometry>
            <material name="">
                <color rgba="0.890196078431372 0.890196078431372 0.913725490196078 1"/>
            </material>
        </visual>
    </link>


    <joint name="shoulder_roll_joint_R" type="revolute">
        <origin xyz="0.0275 -0.0636 0" rpy="0 0 0"/>
        <parent link="shoulder_pitch_R"/>
        <child link="shoulder_roll_R"/>
        <axis xyz="-1 0 0"/>
        <limit
                lower="-0.0873"
                upper="1.7453"
                effort="40"
                velocity="10"/>
    </joint>
    <link name="shoulder_roll_R">
        <inertial>
            <origin
                    xyz="-0.025 0.0 -0.075"
                    rpy="0 0 0"/>
            <mass value="0.929"/>
            <inertia
                    ixx="1371.975032E-06"
                    ixy="1.029439E-06"
                    ixz="-221.939509E-06"
                    iyy="1515.198843E-06"
                    iyz="0.435620E-06"
                    izz="873.513514E-06"/>
        </inertial>
        <visual>
            <origin
                    xyz="0 0 0"
                    rpy="0 0 0"/>
            <geometry>
                <mesh filename="../meshes/shoulder_roll_R.STL"/>
            </geometry>
            <material name="">
                <color rgba="0.890196078431372 0.890196078431372 0.913725490196078 1"/>
            </material>
        </visual>
    </link>

    <joint name="shoulder_yaw_joint_R" type="revolute">
        <origin xyz="-0.0275 0 -0.112" rpy="0 0 0"/>
        <parent link="shoulder_roll_R"/>
        <child link="shoulder_yaw_R"/>
        <axis xyz="0 0 1"/>
        <limit
                lower="-1.5708"
                upper="0.7854"
                effort="40"
                velocity="10"/>
    </joint>
    <link name="shoulder_yaw_R">
        <inertial>
            <origin
                    xyz="-0.00086 0.0 -0.14858"
                    rpy="0 0 0"/>
            <mass value="1.075"/>
            <inertia
                    ixx="3440.482150E-06"
                    ixy="2.799463E-06"
                    ixz="-40.730553E-06"
                    iyy="3425.016102E-06"
                    iyz="-44.252680E-06"
                    izz="865.590773E-06"/>
        </inertial>
        <visual>
            <origin
                    xyz="0 0 0"
                    rpy="0 0 0"/>
            <geometry>
                <mesh filename="../meshes/shoulder_yaw_R.STL"/>
            </geometry>
            <material name="">
                <color rgba="0.898039215686275 0.917647058823529 0.929411764705882 1"/>
            </material>
        </visual>
        <collision>
            <origin rpy="0 0 0" xyz="0 0 -0.02"/>
            <geometry>
                <cylinder radius="0.04" length="0.16"/>
            </geometry>
        </collision>
    </link>


    <joint name="elbow_joint_R" type="revolute">
        <origin xyz="0 -0.0275 -0.1719" rpy="0 0 0"/>
        <parent link="shoulder_yaw_R"/>
        <child link="elbow_R"/>
        <axis xyz="0 -1 0"/>
        <limit
                lower="-1.5708"
                upper="0.5787"
                effort="40"
                velocity="10"/>
    </joint>
    <link name="elbow_R">
        <inertial>
            <origin
                    xyz="0.08954 0.0209 -0.000106"
                    rpy="0 0 0"/>
            <mass value="0.278"/>
            <inertia
                    ixx="217.677566E-06"
                    ixy="-164.011059E-06"
                    ixz="-1.889902E-06"
                    iyy="2128.203072E-06"
                    iyz="-0.871789E-06"
                    izz="2247.922760E-06"/>
        </inertial>
        <visual>
            <origin
                    xyz="0 0 0"
                    rpy="0 0 0"/>
            <geometry>
                <mesh filename="../meshes/elbow_R.STL"/>
            </geometry>
            <material name="">
                <color rgba="0.890196078431372 0.890196078431372 0.913725490196078 1"/>
            </material>
        </visual>
        <collision>
            <origin
                    xyz="0 0 0"
                    rpy="0 0 0"/>
            <geometry>
                <mesh filename="../meshes/elbow_R.STL"/>
            </geometry>
        </collision>
    </link>


    <!-- Right hand Contact -->
    <joint name="contact_hand_joint_R" type="fixed" dont_collapse="true">
        <origin xyz="0.274 0.0275 0.0" rpy="0 0 0"/>
        <parent link="elbow_R"/>
        <child link="contact_hand_R"/>
    </joint>
    <link name="contact_hand_R">
        <inertial>
            <origin xyz=".0 .0 .0" rpy="0 0 0"/>
            <mass value="0.001"/>
            <inertia ixx="0.0000001" ixy="0.0" ixz="0.0" iyy="0.0000001" iyz="0.0" izz="0.0000001"/>
        </inertial>
        <visual>
            <origin xyz="0 0 0" rpy="0 0 0"/>
            <geometry>
                <box size="0.01 0.01 0.01"/>
            </geometry>
            <material name="">
                <color rgba="1 0 0 1"/>
            </material>
        </visual>
    </link>

    <!-- Right Leg -->
    <joint name="hip_roll_joint_R" type="revolute">
        <origin xyz="-0.068 -0.118 -0.03116" rpy="0 0 0"/>
        <parent link="base_link"/>
        <child link="hip_roll_R"/>
        <axis xyz="-1 0 0"/>
        <limit
                lower="-0.5236"
                upper="0.5236"
                effort="120"
                velocity="20"/>
    </joint>
    <link name="hip_roll_R">
        <inertial>
            <origin
                    xyz="0.0711 0 0.0032"
                    rpy="0 0 0"/>
            <mass value="1.353"/>
            <inertia
                    ixx="1474.595577E-06"
                    ixy="-0.035621E-06"
                    ixz="2.830837E-06"
                    iyy="2445.648862E-06"
                    iyz="4.252336E-06"
                    izz="2855.882505E-06"/>
        </inertial>
        <visual>
            <origin
                    xyz="0 0 0"
                    rpy="0 0 0"/>
            <geometry>
                <mesh filename="../meshes/hip_roll_R.STL"/>
            </geometry>
            <material name="">
                <color rgba="0.898039215686275 0.917647058823529 0.929411764705882 1"/>
            </material>
        </visual>
        <collision>
            <origin
                    xyz="-0.04 0 0"
                    rpy="0 0 0"/>
            <geometry>
                <box size="0.07 0.1 0.1"/>
            </geometry>
        </collision>
    </link>

    <joint name="hip_yaw_joint_R" type="revolute">
        <origin xyz="0.068 0 -0.0195" rpy="0 0 0"/>
        <parent link="hip_roll_R"/>
        <child link="hip_yaw_R"/>
        <axis xyz="0 0 -1"/>
        <limit
                lower="-0.7854"
                upper="0.7854"
                effort="120"
                velocity="20"/>
    </joint>
    <link name="hip_yaw_R">
        <inertial>
            <origin
                    xyz="0 0.03166 -0.0877"
                    rpy="0 0 0"/>
            <mass value="1.999"/>
            <inertia
                    ixx="6363.143641E-06"
                    ixy="2.235936E-06"
                    ixz="-1.625167E-06"
                    iyy="6565.890011E-06"
                    iyz="1068.019977E-06"
                    izz="4234.229362E-06"/>
        </inertial>
        <visual>
            <origin
                    xyz="0 0 0"
                    rpy="0 0 0"/>
            <geometry>
                <mesh filename="../meshes/hip_yaw_R.STL"/>
            </geometry>
            <material name="">
                <color rgba="0.792156862745098 0.819607843137255 0.933333333333333 1"/>
            </material>
        </visual>
    </link>


    <joint name="hip_pitch_joint_R" type="revolute">
        <origin xyz="0 0.024 -0.103" rpy="0 0 0"/>
        <parent link="hip_yaw_R"/>
        <child link="hip_pitch_R"/>
        <axis xyz="0 1 0"/>
        <limit
                lower="-1.0472"
                upper="1.5359"
                effort="120"
                velocity="20"/>
    </joint>
    <link name="hip_pitch_R">
        <inertial>
            <origin
                    xyz="0.0202 -0.055 -0.03835"
                    rpy="0 0 0"/>
            <mass value="4.306"/>
            <inertia
                    ixx="39234.883902E-06"
                    ixy="-2770.935796E-06"
                    ixz="16398.509235E-06"
                    iyy="49317.347468E-06"
                    iyz="5316.711707E-06"
                    izz="18132.628369E-06"/>
        </inertial>
        <visual>
            <origin
                    xyz="0 0 0"
                    rpy="0 0 0"/>
            <geometry>
                <mesh filename="../meshes/hip_pitch_R.STL"/>
            </geometry>
            <material name="">
                <color rgba="0.898039215686275 0.917647058823529 0.929411764705882 1"/>
            </material>
        </visual>
        <collision>
            <origin rpy="1.57 0 0" xyz="0 -0.02 0"/>
            <geometry>
                <cylinder radius="0.07" length="0.18"/>
            </geometry>
        </collision>
        <collision>
            <origin rpy="1.57 -0.45 0" xyz="0.1 -0.025 -0.18"/>
            <geometry>
                <box size="0.1 0.24 0.04"/>
            </geometry>
        </collision>
    </link>


    <joint name="knee_joint_R" type="revolute">
        <origin xyz="0.175 -0.024 -0.30311" rpy="0 0 0"/>
        <parent link="hip_pitch_R"/>
        <child link="knee_R"/>
        <axis xyz="0 1 0"/>
        <limit
                lower="-0.6981"
                upper="1.0472"
                effort="180"
                velocity="10"/>
    </joint>
    <link name="knee_R">
        <inertial>
            <origin
                    xyz="-0.06018 0.00312 -0.1125"
                    rpy="0 0 0"/>
            <mass value="1.694"/>
            <inertia
                    ixx="13325.678709E-06"
                    ixy="-520.920143E-06"
                    ixz="-7926.961445E-06"
                    iyy="18655.420898E-06"
                    iyz="-478.732558E-06"
                    izz="6610.199995E-06"/>
        </inertial>
        <visual>
            <origin
                    xyz="0 0 0"
                    rpy="0 0 0"/>
            <geometry>
                <mesh filename="../meshes/knee_R.STL"/>
            </geometry>
            <material name="">
                <color rgba="0.890196078431372 0.890196078431372 0.913725490196078 1"/>
            </material>
        </visual>
        <collision>
            <origin rpy="1.57 0.6 0" xyz="-0.12 -0.0 -0.18"/>
            <geometry>
                <box size="0.08 0.24 0.04"/>
            </geometry>
        </collision>
    </link>

    <joint name="ankle_joint_R" type="revolute">
        <origin xyz="-0.175 0 -0.30311" rpy="0 0 0"/>
        <parent link="knee_R"/>
        <child link="ankle_R"/>
        <axis xyz="0 1 0"/>
        <limit
                lower="-0.6109"
                upper="1.2566"
                effort="40"
                velocity="10"/>
    </joint>
    <link name="ankle_R">
        <inertial>
            <origin
                    xyz="-0.01054 -0.001 -0.021"
                    rpy="0 0 0"/>
            <mass value="0.404"/>
            <inertia
                    ixx="164.737831E-06"
                    ixy="-15.856723E-06"
                    ixz="68.793585E-06"
                    iyy="1149.965027E-06"
                    iyz="8.127539E-06"
                    izz="1159.669589E-06"/>
        </inertial>
        <visual>
            <origin
                    xyz="0 0 0"
                    rpy="0 0 0"/>
            <geometry>
                <mesh filename="../meshes/ankle_R.STL"/>
            </geometry>
            <material name="">
                <color rgba="0.898039215686275 0.917647058823529 0.929411764705882 1"/>
            </material>
        </visual>
        <collision>
            <origin rpy="0 0 0" xyz="0 0 -0.029"/>
            <geometry>
                <box size="0.21 0.06 0.02"/>
            </geometry>
        </collision>
        <!-- <collision>
          <origin
            xyz="0 0 0"
            rpy="0 0 0" />
          <geometry>
            <mesh
              filename="../meshes/ankle_R.STL" />
          </geometry>
        </collision> -->
    </link>

    <!-- Right Foot Contact -->
    <joint name="contact_foot_heel_joint_R" type="fixed">
        <origin xyz="-0.105 0 -0.039" rpy="0 0 0"/>
        <parent link="ankle_R"/>
        <child link="contact_foot_heel_R"/>
    </joint>
    <link name="contact_foot_heel_R">
        <inertial>
            <origin xyz=".0 .0 .0" rpy="0 0 0"/>
            <mass value="0.001"/>
            <inertia ixx="0.0000001" ixy="0.0" ixz="0.0" iyy="0.0000001" iyz="0.0" izz="0.0000001"/>
        </inertial>
        <visual>
            <origin xyz="0 0 0" rpy="0 0 0"/>
            <geometry>
                <box size="0.01 0.01 0.01"/>
            </geometry>
            <material name="red">
                <color rgba="1 0 0 1"/>
            </material>
        </visual>
    </link>

    <joint name="contact_foot_tip_joint_R" type="fixed">
        <origin xyz="0.105 0 -0.039" rpy="0 0 0"/>
        <parent link="ankle_R"/>
        <child link="contact_foot_tip_R"/>
    </joint>
    <link name="contact_foot_tip_R">
        <inertial>
            <origin xyz=".0 .0 .0" rpy="0 0 0"/>
            <mass value="0.001"/>
            <inertia ixx="0.0000001" ixy="0.0" ixz="0.0" iyy="0.0000001" iyz="0.0" izz="0.0000001"/>
        </inertial>
        <visual>
            <origin xyz="0 0 0" rpy="0 0 0"/>
            <geometry>
                <box size="0.01 0.01 0.01"/>
            </geometry>
            <material name="red">
                <color rgba="1 0 0 1"/>
            </material>
        </visual>
    </link>

    <joint name="contact_foot_center_joint_R" type="fixed">
        <origin xyz="0 0 -0.039" rpy="0 0 0"/>
        <parent link="ankle_R"/>
        <child link="contact_foot_center_R"/>
    </joint>
    <link name="contact_foot_center_R">
        <inertial>
            <origin xyz=".0 .0 .0" rpy="0 0 0"/>
            <mass value="0.001"/>
            <inertia ixx="0.0000001" ixy="0.0" ixz="0.0" iyy="0.0000001" iyz="0.0" izz="0.0000001"/>
        </inertial>
        <visual>
            <origin xyz="0 0 0" rpy="0 0 0"/>
            <geometry>
                <box size="0.01 0.01 0.01"/>
            </geometry>
            <material name="red">
                <color rgba="1 0 0 1"/>
            </material>
        </visual>
    </link>
</robot>